Workbook
Name EVT_HAI: #REF!
Name RA_NRO: #REF!
Name AK_SER: #REF!
Name NL_LOU: #REF!
Name EP_ROO: #REF!
Name EVT_VAL: #REF!
Name ACC_TAGS: REF_CODES!$J$187:$J$189
Name RA_DNA: #REF!
Name EVT_ANE: #REF!
Name AU_ELI: #REF!
Name TR_BEL: #REF!
Name SE_SUR: #REF!
Name NL_LIV: #REF!
Name EVT_BRB: #REF!
Name KD_ACT: #REF!
Name EP_GAL: #REF!
Name EVT_PHO: #REF!
Name EP_BIV: #REF!
Name LAB_TBL: #REF!
Name NPS_PASSI: #REF!
Name KD_KFR: #REF!
Name SECURITE: REF_CODES!$J$62:$J$66
Name EVT_CHE: #REF!
Name EVT_MIX: #REF!
Name LAB_LHW: #REF!
Name LIEU_LIB: REF_CODES!$C$142:$C$157
Name EVT_SOU: #REF!
Name ACTIVITE: REF_CODES!$J$27:$J$33
Name EVT_FXS: #REF!
Name EVT_MAS: #REF!
Name EP_POL: #REF!
Name AU_EXC: #REF!
Name EVT_PYR: #REF!
Name EVT_ARC: #REF!
Name EVT_HAM: #REF!
Name EP_BEA: #REF!
Name SE_ETU: #REF!
Name EP_PAL: #REF!
Name TRANSPORT_LIB: REF_CODES!$C$250:$C$261
Name LAB_RC: #REF!
Name TRANSPORT: REF_CODES!$J$58:$J$61
Name LAB_SLH: #REF!
Name AK_NAT: #REF!
Name EVT_NAI: #REF!
Name SE_FEM: #REF!
Name LAB_CN: #REF!
Name NL_IMM: #REF!
Name EP_RES: #REF!
Name TR_SUV: #REF!
Name EVT_FLO: #REF!
Name FID_HOT: #REF!
Name FID_AMB: #REF!
Name EVENEMENTIEL: REF_CODES!$J$87:$J$132
Name AMB_ROM: #REF!
Name NL_SHO: #REF!
Name ST_ULT: #REF!
Name RA_NFE: #REF!
Name EVT_DJ: #REF!
Name RA_NVE: #REF!
Name AMB_FAM: #REF!

Sheet 🌐 PAGE WEB · PARCOURS
A1: 🌐 PAGE WEB · PARCOURS CLIENT
A2: Source de vérité du parcours utilisateur SOLYVENTS · 5 étapes · de la configuration à la confirmation
A3: ✅ V1 · vérifié · aligné sur 🔖 CODES DE RÉFÉRENCE
B4: 📌 SOURCE DE VÉRITÉ DU PARCOURS CLIENT
B5: Cet onglet décrit l'expérience client (ce qu'il VOIT, ce qu'il CHOISIT, et les RÈGLES MÉTIER de chaque saisie). Les CODES et LIBELLÉS font foi dans 🔖 CODES DE RÉFÉRENCE (Bible data → CRM) : le référentiel s'aligne sur le dictionnaire, pas l'inverse. Parcours et dictionnaire sont complémentaires : l'un définit l'expérience, l'autre l'identité des codes.
B10: ⚙️ DOCTRINE FONDAMENTALE · STRUCTURE vs CONTENU
B11: Les éléments listés dans cet onglet (codes AU-*, RA-D*, RA-N*, NL-*, AK-*) ne sont PAS figés dans le référentiel : ce sont des STRUCTURES. La VÉRITÉ vient du CRM SOLYVENTS : • Le RÉFÉRENTIEL définit la STRUCTURE (catégories / sous-catégories / codes) • Le CRM contient le CONTENU (prestations concrètes de fiches presta validées en statut QUA ou DER) • Le MOTEUR orchestre le MATCHING client ↔ presta À chaque slot du parcours, les éléments affichés au client sont DÉVERSÉS depuis le CRM (fiches presta disponibles au moment de la consultation).
B17: ═══ ÉTAPE 1 · CONFIGURATION DU SÉJOUR ═══
B19: 1.1 · 📅 DATES DU SÉJOUR
B20: Saisie | C20: Date d'arrivée + Date de départ
B21: Déduit auto | C21: • Nombre de nuits • Nombre de jours à programmer en ÉTAPE 2
B23: 1.2 · 👥 COMPOSITION DU GROUPE
B24: Saisie | C24: • Compteur Nombre d'ADULTES • Compteur Nombre d'ENFANTS • ÂGE de chaque enfant (nécessaire pour pré-calc chambres et slot Enfants)
B25: ⚙️ Règle | C25: IF nb_enfants > 0 → afficher slot "ENFANTS" en ÉTAPE 2
B27: 1.3 · 🚉 MODE D'ARRIVÉE À MARRAKECH
B28: Saisie | C28: Question single-select : Par quel moyen vous rendrez-vous à Marrakech ?
B29: ✈️ Avion | C29: Message auto : "Je confie à SOLY le soin de gérer l'ensemble de mes déplacements" → gestion_transport = SOLY_GERE (forcé)
B30: 🚄 Train | C30: Message auto : idem AVION → gestion_transport = SOLY_GERE (forcé)
B31: 🚗 Voiture | C31: Deux cases à cocher proposées : ☐ "Je gère seul mes déplacements" → gestion_transport = CLIENT_GERE ☐ "Je confie à SOLY le soin de gérer l'ensemble de mes déplacements" → gestion_transport = SOLY_GERE
B32: Variables | C32: • mode_arrivee (enum : AVION / TRAIN / VOITURE) → NIVEAU 1 • gestion_transport (enum : SOLY_GERE / CLIENT_GERE) → NIVEAU 1 PAS de famille de codes dédiée · simple champ technique
B34: 1.4 · 🎨 ESPRIT DU SÉJOUR · OR-*
B35: Affichage | C35: 5 cartes visuelles · single-select obligatoire
B36: OR-ZEN | C36: ZEN & BIEN-ÊTRE
B37: OR-ROM | C37: ROMANTIQUE
B38: OR-FAM | C38: FAMILIAL
B39: OR-FES | C39: FESTIF
B40: OR-PRO | C40: PROFESSIONNEL
B42: 1.5 · 🏨 PRISE EN CHARGE HÉBERGEMENT PAR SOLYVENTS
B43: Question | C43: Oui / Non
B44: ⚙️ Si NON | C44: Pas de questions 1.5.1/1.5.2/1.5.3 · passage direct à ÉTAPE 2
B45: ⚙️ Si OUI | C45: Sous-questions 1.5.1 + 1.5.2 + 1.5.3 obligatoires
B47: 1.5.1 · 🛏️ | C47: NOMBRE DE CHAMBRES
B48: Algorithme | C48: Compteur PRÉ-CALCULÉ par défaut selon règle : • 2 adultes / chambre par défaut • Enfants < 12 ans → dans chambre des parents (avec les parents en hôtel) • Enfants ≥ 12 ans → 1 chambre supplémentaire Ajustement possible par le client (peut augmenter ou diminuer)
B49: Exemples | C49: • 2 adultes + 1 enfant 5 ans = 1 chambre • 2 adultes + 2 enfants 7 et 10 ans = 1 chambre • 2 adultes + 1 enfant 14 ans = 2 chambres • 4 adultes = 2 chambres • 4 adultes + 1 ado 15 ans = 3 chambres
B51: 1.5.2 · 🏛️ | C51: ATMOSPHÈRE DU SÉJOUR · HB-*
B52: Affichage | C52: 6 cartes · single-select
B53: HB-HOT | C53: HOTEL & RESORT
B54: HB-INC | C54: INCONTOURNABLE
B55: HB-RIA | C55: RIAD & PATRIMOINE
B56: HB-COL | C56: COLLECTION PRIVÉE
...

Sheet 🔖 CODES DE RÉFÉRENCE
A1: 🔖 CODES DE RÉFÉRENCE — ✅ V1 vérifié (BIBLE) · réordonné selon le PARCOURS WEB · 4 systèmes : WEB · ONB · MOTEUR/CRM · APP
A2: 📜 DOCTRINE · Le MOTEUR/CRM ne génère jamais une donnée ex nihilo : ses algorithmes s'appuient sur les données récoltées à l'ONBOARDING. Onboarding = matière première · Moteur = transformation.
A3: ━━━━━ ▼ BLOC CLIENT · familles du PARCOURS WEB (WEB ✓) ━━━━━
A4: ━━ OR · ORIENTATION CLIENT (5 codes) ━━ ESPRIT DU SEJOUR
A5: FAMILLE | B5: CODE | C5: LIBELLÉ | D5: DESCRIPTION | E5: WEB | F5: ONB | G5: MOTEUR/CRM | H5: APP | I5: STATUT | J5: USAGE
A6: OR | B6: OR-ZEN | C6: ZEN & BIEN-ÊTRE | D6: Boost spa/yoga/healing · sérénité | E6: ✓ | F6: ✓ | G6: ✓ | H6: – | I6: ✅ V1 | J6: Parcours web · Matching
A7: OR | B7: OR-ROM | C7: ROMANTIQUE | D7: Boost suite privée · rooftop sunset · dîner désert | E7: ✓ | F7: ✓ | G7: ✓ | H7: – | I7: ✅ V1 | J7: Parcours web · Matching
A8: OR | B8: OR-FAM | C8: FAMILIAL | D8: Boost resort · villa · kids club | E8: ✓ | F8: ✓ | G8: ✓ | H8: – | I8: ✅ V1 | J8: Parcours web · Matching
A9: OR | B9: OR-FES | C9: FESTIF | D9: Boost villa privatisable · rooftop · DJ · nightlife | E9: ✓ | F9: ✓ | G9: ✓ | H9: – | I9: ✅ V1 | J9: Parcours web · Matching
A10: OR | B10: OR-PRO | C10: PROFESSIONNEL | D10: Boost hôtel 5⁎ · palace · lounge business | E10: ✓ | F10: ✓ | G10: ✓ | H10: – | I10: ✅ V1 | J10: Parcours web · Matching
A11: ━━ HB · HÉBERGEMENT (6 codes) ━━ TYPE HEBERGEMENT
A12: FAMILLE | B12: CODE | C12: LIBELLÉ | D12: DESCRIPTION | E12: WEB | F12: ONB | G12: MOTEUR/CRM | H12: APP | I12: STATUT | J12: USAGE
A13: HB | B13: HB-HOT | C13: HOTEL & RESORT | D13: Hôtel 4⁎ · Hôtel 5⁎ · Resort | E13: ✓ | F13: ✓ | G13: ✓ | H13: – | I13: ✅ V1 | J13: Parcours web · Matching
A14: HB | B14: HB-INC | C14: INCONTOURNABLE | D14: Palace · Relais & Châteaux · Boutique hôtel | E14: ✓ | F14: ✓ | G14: ✓ | H14: – | I14: ✅ V1 | J14: Parcours web · Matching
A15: HB | B15: HB-RIA | C15: RIAD & PATRIMOINE | D15: Riad · Palais d'hôtes | E15: ✓ | F15: ✓ | G15: ✓ | H15: – | I15: ✅ V1 | J15: Parcours web · Matching
A16: HB | B16: HB-COL | C16: COLLECTION PRIVÉE | D16: Riad privatisable · Villa privée · Domaine privé | E16: ✓ | F16: ✓ | G16: ✓ | H16: – | I16: ✅ V1 | J16: Parcours web · Matching
A17: HB | B17: HB-NAT | C17: NATURE & HORIZON | D17: Desert Camp · Desert Resort · Lodge | E17: ✓ | F17: ✓ | G17: ✓ | H17: – | I17: ✅ V1 | J17: Parcours web · Matching
A18: HB | B18: HB-SUR | C18: SUR MESURE ABSOLU | D18: MODE COMBINAISON : le client assemble 2 types d'hébergement OU PLUS sur le séjour (ex : riad médina + camp désert). N'est PAS un 6e type — voyage multi-lieux composé par SOLY. · IMPOSE automatiquement BG-LIBRE (le client ne choisit pas de tranche BG1–BG5). | E18: ✓ | F18: ✓ | G18: ✓ | H18: – | I18: ✅ V1 | J18: Parcours web · Matching
A19: ━━ BG · BUDGET (6 codes) ━━ BUDGET HEBERGEMENT PAR NUIT ET PAR CHAMBRE
A20: FAMILLE | B20: CODE | C20: LIBELLÉ | D20: DESCRIPTION | E20: WEB | F20: ONB | G20: MOTEUR/CRM | H20: APP | I20: STATUT | J20: USAGE
A21: BG | B21: BG1 | C21: Moins de 300 € | D21: Budget moyen / nuit / chambre | E21: ✓ | F21: ✓ | G21: ✓ | H21: – | I21: ✅ V1 | J21: Parcours web · Onboarding · Matching
A22: BG | B22: BG2 | C22: 300 – 500 € | D22: Budget moyen / nuit / chambre | E22: ✓ | F22: ✓ | G22: ✓ | H22: – | I22: ✅ V1 | J22: Parcours web · Onboarding · Matching
A23: BG | B23: BG3 | C23: 500 – 800 € | D23: Budget moyen / nuit / chambre | E23: ✓ | F23: ✓ | G23: ✓ | H23: – | I23: ✅ V1 | J23: Parcours web · Onboarding · Matching
A24: BG | B24: BG4 | C24: 800 – 1 200 € | D24: Budget moyen / nuit / chambre | E24: ✓ | F24: ✓ | G24: ✓ | H24: – | I24: ✅ V1 | J24: Parcours web · Onboarding · Matching
A25: BG | B25: BG5 | C25: 1 200 € et + | D25: Budget moyen / nuit / chambre | E25: ✓ | F25: ✓ | G25: ✓ | H25: – | I25: ✅ V1 | J25: Parcours web · Onboarding · Matching
A26: BG | B26: BG-LIBRE | C26: SUR MESURE | D26: Budget sur mesure (composé) · désactive le filtre · EXCLUSIVEMENT lié à HB-SUR — jamais proposé avec un hébergement classique (HB-HOT/INC/RIA/COL/NAT), qui utilisent BG1–BG5. | E26: ✓ | F26: ✓ | G26: ✓ | H26: – | I26: ✅ V1 | J26: Parcours web · Onboarding · Matching
A27: ━━ EV · ÉVÉNEMENTS (5 standards · V1) ━━ AVEZ-VOUS UN EVENEMENT A CELEBRER DURANT LE SEJOUR
A28: EV | B28: EV-DEM | C28: DEMANDE EN MARIAGE | D28: 2 adultes · pack CRM (PACK1/PACK2) | E28: ✓ | F28: – | G28: ✓ | H28: – | I28: ✅ V1 | J28: Parcours web · Matching
A29: EV | B29: EV-ANN | C29: ANNIVERSAIRE (parent) | D29: Catégorie parente · 2 sous-choix : festif (EV-AFE) / familial (EV-AFA) · seul le familial ouvre le nb d'enfants | E29: ✓ | F29: – | G29: ✓ | H29: – | I29: ✅ V1 | J29: Parcours web · Matching
A30: EV | B30: EV-AFE | C30: ANNIVERSAIRE FESTIF | D30: Ambiance fête · ≥5 adultes · pack CRM | E30: ✓ | F30: – | G30: ✓ | H30: – | I30: ✅ V1 | J30: Parcours web · Matching
A31: EV | B31: EV-AFA | C31: ANNIVERSAIRE FAMILIAL | D31: Cadre intime famille · ≥5 ad · pack CRM | E31: ✓ | F31: – | G31: ✓ | H31: – | I31: ✅ V1 | J31: Parcours web · Matching
A32: EV | B32: EV-EVJF | C32: EVJF | D32: ≥5 adultes · pack CRM | E32: ✓ | F32: – | G32: ✓ | H32: – | I32: ✅ V1 | J32: Parcours web · Matching
A33: EV | B33: EV-EVG | C33: EVG | D33: ≥5 adultes · pack CRM | E33: ✓ | F33: – | G33: ✓ | H33: – | I33: ✅ V1 | J33: Parcours web · Matching
A34: EV | B34: EV-AUT | C34: AUTRE (cas par cas) | D34: Champ libre · SOLY ASSISTANCE 24h · pas de pack CRM | E34: ✓ | F34: – | G34: ✓ | H34: – | I34: ✅ V1 | J34: Parcours web · Matching
A35: 📌 V1 · RAPPEL DOCTRINE • Les codes ci-dessus complètent les familles V1 conservées plus bas • Tous les codes (V1 + V1/V1) sont utilisés dans le PARCOURS · le MOTEUR · le CRM · l'INGESTION • Les codes V1/V1 NL-*/AK-*/TR-* sont multi-select sur les slots du parcours • Les 5 EV-* STANDARDS (DEM/AFE/AFA/EVJF/EVG) déclenchent 2 PACKS CRM (sauf EV-AUT cas par cas) EV-AUT (Autre) → le conseiller SOLY puise dans une bibliothèque interne back-office (13 packs sur-mesure) — liste détaillée dans MASTER_TAGS (famille EV-INTERNE) · référencée aussi dans MATCHING ⚠ EV-* (types d'événement) ≠ EVT-* (prestataires événementiel · voir onglet EVT) — NE PAS CONFONDRE
A36: ━━ AU · ACTIVITÉ · UNIVERS (7 codes) ━━ ACTIVITE AU CHOIX BLOC MATIN BLOC APRES MIDI ET BLOC ENFANTS
A37: FAMILLE | B37: CODE | C37: LIBELLÉ | D37: DESCRIPTION | E37: WEB | F37: ONB | G37: MOTEUR/CRM | H37: APP | I37: STATUT | J37: USAGE
A38: AU | B38: AU-EXC | C38: EXCURSION À LA JOURNÉE | D38: Sortie à la journée hors Marrakech · Destinations : Désert d'Agafay · Vallée de l'Ourika · Cascades d'Ouzoud · Essaouira · Imlil & Atlas · Aït Ben Haddou / Ouarzazate · Lac Lalla Takerkoust · Vallée des 3 Palmiers · 🌅 DÉPART MATINÉE — journée complète · ⚠ EXCLUSIF : désactive automatiquement les blocs DÉJEUNER + APRÈS-MIDI → seuls DÎNER + SOIRÉE restent sélectionnables · Transport + guide selon prestation | E38: ✓ | F38: ✓ | G38: ✓ | H38: – | I38: ✅ V1 | J38: Parcours web · Matching
A39: AU | B39: AU-DES | C39: DÉSERT & HORIZONS | E39: ✓ | F39: ✓ | G39: ✓ | H39: – | I39: ✅ V1 | J39: Parcours web · Matching
A40: AU | B40: AU-SPO | C40: SPORT & ÉNERGIE | D40: Golf · Yoga · Pilates · Padel · Tennis · Surf · Karting · Équitation · VTT · Escalade · Fitness · 🌅🌴 matin + après-midi | E40: ✓ | F40: ✓ | G40: ✓ | H40: – | I40: ✅ V1 | J40: Parcours web · Matching
...

Sheet REF_CODES
A1: 🧩 REF_CODES · MIROIR VIVANT de « 🔖 CODES DE RÉFÉRENCE » · LIBELLÉ (C) + DESCRIPTION (D) + CODE+LIBELLÉ (J) = formules XLOOKUP auto-synchronisées depuis la bible (toute modif de libellé/description dans la bible se répercute ici automatiquement). ⚠️ NE PAS éditer C/D/J à la main. Colonne CODE (B) FIGÉE = ancre des ~1759 lookups · ne pas réordonner/insérer/supprimer de lignes. Ajout/suppression de code dans la bible = resync manuel du code (B) + carte des plages ci-dessous (demandez-moi).
A2: FAMILLE | B2: CODE | C2: LIBELLÉ | D2: DESCRIPTION | E2: WEB | F2: ONB | G2: MOTEUR/CRM | H2: APP | I2: STATUT | J2: CODE + LIBELLÉ
A3: OR | B3: OR-ZEN | C3: {=XLOOKUP($B3,'🔖 CODES DE RÉFÉRENCE'!$B:$B,'🔖 CODES DE RÉFÉRENCE'!$C:$C,"")} -> ZEN & BIEN-ÊTRE | D3: {=XLOOKUP($B3,'🔖 CODES DE RÉFÉRENCE'!$B:$B,'🔖 CODES DE RÉFÉRENCE'!$D:$D,"")} -> Boost spa/yoga/healing · sérénité | E3: ✓ | F3: ✓ | G3: ✓ | H3: – | I3: ✅ V1 | J3: =$B3&" — "&$C3 -> OR-ZEN — ZEN & BIEN-ÊTRE
A4: OR | B4: OR-ROM | C4: {=XLOOKUP($B4,'🔖 CODES DE RÉFÉRENCE'!$B:$B,'🔖 CODES DE RÉFÉRENCE'!$C:$C,"")} -> ROMANTIQUE | D4: {=XLOOKUP($B4,'🔖 CODES DE RÉFÉRENCE'!$B:$B,'🔖 CODES DE RÉFÉRENCE'!$D:$D,"")} -> Boost suite privée · rooftop sunset · dîner désert | E4: ✓ | F4: ✓ | G4: ✓ | H4: – | I4: ✅ V1 | J4: =$B4&" — "&$C4 -> OR-ROM — ROMANTIQUE
A5: OR | B5: OR-FAM | C5: {=XLOOKUP($B5,'🔖 CODES DE RÉFÉRENCE'!$B:$B,'🔖 CODES DE RÉFÉRENCE'!$C:$C,"")} -> FAMILIAL | D5: {=XLOOKUP($B5,'🔖 CODES DE RÉFÉRENCE'!$B:$B,'🔖 CODES DE RÉFÉRENCE'!$D:$D,"")} -> Boost resort · villa · kids club | E5: ✓ | F5: ✓ | G5: ✓ | H5: – | I5: ✅ V1 | J5: =$B5&" — "&$C5 -> OR-FAM — FAMILIAL
A6: OR | B6: OR-FES | C6: {=XLOOKUP($B6,'🔖 CODES DE RÉFÉRENCE'!$B:$B,'🔖 CODES DE RÉFÉRENCE'!$C:$C,"")} -> FESTIF | D6: {=XLOOKUP($B6,'🔖 CODES DE RÉFÉRENCE'!$B:$B,'🔖 CODES DE RÉFÉRENCE'!$D:$D,"")} -> Boost villa privatisable · rooftop · DJ · nightlife | E6: ✓ | F6: ✓ | G6: ✓ | H6: – | I6: ✅ V1 | J6: =$B6&" — "&$C6 -> OR-FES — FESTIF
A7: OR | B7: OR-PRO | C7: {=XLOOKUP($B7,'🔖 CODES DE RÉFÉRENCE'!$B:$B,'🔖 CODES DE RÉFÉRENCE'!$C:$C,"")} -> PROFESSIONNEL | D7: {=XLOOKUP($B7,'🔖 CODES DE RÉFÉRENCE'!$B:$B,'🔖 CODES DE RÉFÉRENCE'!$D:$D,"")} -> Boost hôtel 5⁎ · palace · lounge business | E7: ✓ | F7: ✓ | G7: ✓ | H7: – | I7: ✅ V1 | J7: =$B7&" — "&$C7 -> OR-PRO — PROFESSIONNEL
A8: HB | B8: HB-HOT | C8: {=XLOOKUP($B8,'🔖 CODES DE RÉFÉRENCE'!$B:$B,'🔖 CODES DE RÉFÉRENCE'!$C:$C,"")} -> HOTEL & RESORT | D8: {=XLOOKUP($B8,'🔖 CODES DE RÉFÉRENCE'!$B:$B,'🔖 CODES DE RÉFÉRENCE'!$D:$D,"")} -> Hôtel 4⁎ · Hôtel 5⁎ · Resort | E8: ✓ | F8: ✓ | G8: ✓ | H8: – | I8: ✅ V1 | J8: =$B8&" — "&$C8 -> HB-HOT — HOTEL & RESORT
A9: HB | B9: HB-INC | C9: {=XLOOKUP($B9,'🔖 CODES DE RÉFÉRENCE'!$B:$B,'🔖 CODES DE RÉFÉRENCE'!$C:$C,"")} -> INCONTOURNABLE | D9: {=XLOOKUP($B9,'🔖 CODES DE RÉFÉRENCE'!$B:$B,'🔖 CODES DE RÉFÉRENCE'!$D:$D,"")} -> Palace · Relais & Châteaux · Boutique hôtel | E9: ✓ | F9: ✓ | G9: ✓ | H9: – | I9: ✅ V1 | J9: =$B9&" — "&$C9 -> HB-INC — INCONTOURNABLE
A10: HB | B10: HB-RIA | C10: {=XLOOKUP($B10,'🔖 CODES DE RÉFÉRENCE'!$B:$B,'🔖 CODES DE RÉFÉRENCE'!$C:$C,"")} -> RIAD & PATRIMOINE | D10: {=XLOOKUP($B10,'🔖 CODES DE RÉFÉRENCE'!$B:$B,'🔖 CODES DE RÉFÉRENCE'!$D:$D,"")} -> Riad · Palais d'hôtes | E10: ✓ | F10: ✓ | G10: ✓ | H10: – | I10: ✅ V1 | J10: =$B10&" — "&$C10 -> HB-RIA — RIAD & PATRIMOINE
A11: HB | B11: HB-COL | C11: {=XLOOKUP($B11,'🔖 CODES DE RÉFÉRENCE'!$B:$B,'🔖 CODES DE RÉFÉRENCE'!$C:$C,"")} -> COLLECTION PRIVÉE | D11: {=XLOOKUP($B11,'🔖 CODES DE RÉFÉRENCE'!$B:$B,'🔖 CODES DE RÉFÉRENCE'!$D:$D,"")} -> Riad privatisable · Villa privée · Domaine privé | E11: ✓ | F11: ✓ | G11: ✓ | H11: – | I11: ✅ V1 | J11: =$B11&" — "&$C11 -> HB-COL — COLLECTION PRIVÉE
A12: HB | B12: HB-NAT | C12: {=XLOOKUP($B12,'🔖 CODES DE RÉFÉRENCE'!$B:$B,'🔖 CODES DE RÉFÉRENCE'!$C:$C,"")} -> NATURE & HORIZON | D12: {=XLOOKUP($B12,'🔖 CODES DE RÉFÉRENCE'!$B:$B,'🔖 CODES DE RÉFÉRENCE'!$D:$D,"")} -> Desert Camp · Desert Resort · Lodge | E12: ✓ | F12: ✓ | G12: ✓ | H12: – | I12: ✅ V1 | J12: =$B12&" — "&$C12 -> HB-NAT — NATURE & HORIZON
A13: HB | B13: HB-SUR | C13: {=XLOOKUP($B13,'🔖 CODES DE RÉFÉRENCE'!$B:$B,'🔖 CODES DE RÉFÉRENCE'!$C:$C,"")} -> SUR MESURE ABSOLU | D13: {=XLOOKUP($B13,'🔖 CODES DE RÉFÉRENCE'!$B:$B,'🔖 CODES DE RÉFÉRENCE'!$D:$D,"")} -> MODE COMBINAISON : le client assemble 2 types d'hébergement OU PLUS sur le séjour (ex : riad médina + camp désert). N'est PAS un 6e type — voyage multi-lieux composé par SOLY. · IMPOSE automatiquement BG-LIBRE (le client ne choisit pas de tranche BG1–BG5). | E13: ✓ | F13: ✓ | G13: ✓ | H13: – | I13: ✅ V1 | J13: =$B13&" — "&$C13 -> HB-SUR — SUR MESURE ABSOLU
A14: BG | B14: BG1 | C14: {=XLOOKUP($B14,'🔖 CODES DE RÉFÉRENCE'!$B:$B,'🔖 CODES DE RÉFÉRENCE'!$C:$C,"")} -> Moins de 300 € | D14: {=XLOOKUP($B14,'🔖 CODES DE RÉFÉRENCE'!$B:$B,'🔖 CODES DE RÉFÉRENCE'!$D:$D,"")} -> Budget moyen / nuit / chambre | E14: ✓ | F14: ✓ | G14: ✓ | H14: – | I14: ✅ V1 | J14: =$B14&" — "&$C14 -> BG1 — Moins de 300 €
... A214: ZONE | B214: Z020 | C214: {=XLOOKUP($B214,'🔖 CODES DE RÉFÉRENCE'!$B:$B,'🔖 CODES DE RÉFÉRENCE'!$C:$C,"")} -> Aéroport Menara · Terminal 1 | D214: {=XLOOKUP($B214,'🔖 CODES DE RÉFÉRENCE'!$B:$B,'🔖 CODES DE RÉFÉRENCE'!$D:$D,"")} -> Aéroport | E214: – | F214: ✓ | G214: ✓ | H214: – | I214: 🆕 V1 | J214: =$B214&" — "&$C214 -> Z020 — Aéroport Menara · Terminal 1
A217: 🔒 CARTE DES PLAGES FIGÉES (ex-onglet PLAGES_REF_CODES) · ⚠️ ~1759 INDEX/MATCH pointent sur ces plages absolues · ne PAS insérer/supprimer de lignes dans REF_CODES sans resynchroniser cette carte. | G217: LISTE DÉROULANT ACTIVITES · D (AU 7 + AK 5 = 12)
A218: FAMILLE | B218: LIGNES | C218: NB CODES | D218: PLAGE CODE (col B) | E218: PLAGE LIBELLÉ (col C) | G218: =C27 -> DÉSERT & HORIZONS | H218: –
A219: OR | B219: 3-7 | C219: 5 | D219: $B$3:$B$7 | E219: $C$3:$C$7 | G219: =C28 -> SPORT & ÉNERGIE | H219: –
A220: HB | B220: 8-13 | C220: 6 | D220: $B$8:$B$13 | E220: $C$8:$C$13 | G220: =C29 -> CULTURE & IMMERSION | H220: –
A221: BG | B221: 14-19 | C221: 6 | D221: $B$14:$B$19 | E221: $C$14:$C$19 | G221: =C30 -> BIEN-ÊTRE & RELAXATION | H221: –
A222: EV | B222: 20-26 | C222: 7 | D222: $B$20:$B$26 | E222: $C$20:$C$26 | G222: =C31 -> ÉLITE & SIGNATURE | H222: –
A223: AU | B223: 27-33 | C223: 7 | D223: $B$27:$B$33 | E223: $C$27:$C$33 | G223: =C32 -> EXCURSION À LA JOURNÉE | H223: –
A224: RA-D | B224: 34-39 | C224: 6 | D224: $B$34:$B$39 | E224: $C$34:$C$39 | G224: =C33 -> FESTIF & LIFESTYLE | H224: –
A225: RA-N | B225: 40-45 | C225: 6 | D225: $B$40:$B$45 | E225: $C$40:$C$45 | G225: =C51 -> CRÉATIF & LUDIQUE | H225: –
A226: NL | B226: 46-50 | C226: 5 | D226: $B$46:$B$50 | E226: $C$46:$C$50 | G226: =C52 -> DÉCOUVERTE & APPRENTISSAGE | H226: –
A227: AK | B227: 51-55 | C227: 5 | D227: $B$51:$B$55 | E227: $C$51:$C$55 | G227: =C53 -> NATURE & EXPLORATION | H227: –
A228: RG | B228: 56-57 | C228: 2 | D228: $B$56:$B$57 | E228: $C$56:$C$57 | G228: =C54 -> LOISIRS & ÉNERGIE | H228: –
A229: TR | B229: 58-61 | C229: 4 | D229: $B$58:$B$61 | E229: $C$58:$C$61 | G229: =C55 -> SÉRÉNITÉ PARENTS | H229: –
A230: SE | B230: 62-66 | C230: 5 | D230: $B$62:$B$66 | E230: $C$62:$C$66 | G230: ✓ | H230: –
A231: FID | B231: 67-70 | C231: 4 | D231: $B$67:$B$70 | E231: $C$67:$C$70 | G231: ✓ | H231: –
A232: NPS | B232: 71-74 | C232: 4 | D232: $B$71:$B$74 | E232: $C$71:$C$74 | G232: ✓ | H232: –
A233: ST | B233: 75-77 | C233: 3 | D233: $B$75:$B$77 | E233: $C$75:$C$77 | G233: ✓ | H233: –
A234: AMB | B234: 78-82 | C234: 5 | D234: $B$78:$B$82 | E234: $C$78:$C$82 | G234: ✓ | H234: –
A235: KD | B235: 83-86 | C235: 4 | D235: $B$83:$B$86 | E235: $C$83:$C$86 | G235: ✓ | H235: –
A236: EVT | B236: 87-132 | C236: 46 | D236: $B$87:$B$132 | E236: $C$87:$C$132 | G236: ✓ | H236: –
A237: LABEL | B237: 133-141 | C237: 9 | D237: $B$133:$B$141 | E237: $C$133:$C$141 | G237: ✓ | H237: –
A238: EP | B238: 142-157 | C238: 16 | D238: $B$142:$B$157 | E238: $C$142:$C$157 | G238: ✓ | H238: –
A239: TV | B239: 158-160 | C239: 3 | D239: $B$158:$B$160 | E239: $C$158:$C$160 | G239: ✓ | H239: –
A240: ANC | B240: 161-162 | C240: 2 | D240: $B$161:$B$162 | E240: $C$161:$C$162 | G240: ✓ | H240: –
A241: LVL | B241: 163-167 | C241: 5 | D241: $B$163:$B$167 | E241: $C$163:$C$167 | G241: ✓ | H241: –
...

Sheet MASTER_TAGS
A1: 🏷️ MASTER_TAGS · tags de matching mutualisés · alignés sur 🔖 CODES DE RÉFÉRENCE (bible) · ✅ V1 vérifié
A2: FAMILLE | B2: NOM FAMILLE | C2: CODE | D2: LIBELLÉ | E2: TYPE MATCHING | F2: ONGLETS | G2: CODE + LIBELLÉ | H2: → ÉQUIV. BIBLE / ARBITRAGE
A3: PUBLIC | B3: Occupation cible / publics | C3: PUB-ADU | D3: Adultes uniquement | E3: filtre + tri | F3: TOUS | G3: PUB-ADU · Adultes uniquement
A4: PUBLIC | B4: Occupation cible / publics | C4: PUB-CPL | D4: Couple | E4: filtre + tri | F4: TOUS | G4: PUB-CPL · Couple
A5: PUBLIC | B5: Occupation cible / publics | C5: PUB-FAM | D5: Famille | E5: filtre + tri | F5: TOUS | G5: PUB-FAM · Famille
A6: PUBLIC | B6: Occupation cible / publics | C6: PUB-GRP | D6: Groupe | E6: filtre + tri | F6: TOUS | G6: PUB-GRP · Groupe
A7: PUBLIC | B7: Occupation cible / publics | C7: PUB-PRO | D7: Professionnel | E7: filtre + tri | F7: TOUS | G7: PUB-PRO · Professionnel
A8: PUBLIC | B8: Occupation cible / publics | C8: PUB-SOL | D8: Solo | E8: filtre + tri | F8: TOUS | G8: PUB-SOL · Solo
A9: AMB | B9: Ambiance | C9: AMB-ROM | D9: ROMANTIQUE | E9: tri (scoring) | F9: HEB·RES·ACT·ESP·POI | G9: AMB-ROM · ROMANTIQUE
A10: AMB | B10: Ambiance | C10: AMB-ZEN | D10: ZEN & BIEN-ÊTRE | E10: tri (scoring) | F10: HEB·RES·ACT·ESP·POI | G10: AMB-ZEN · ZEN & BIEN-ÊTRE | H10: ✕ Incompatible avec AMB-FES (zen vs festif) · règle reportée de la bible
A11: AMB | B11: Ambiance | C11: AMB-FES | D11: FESTIF | E11: tri (scoring) | F11: HEB·RES·ACT·ESP·POI | G11: AMB-FES · FESTIF | H11: ✕ Incompatible avec AMB-ZEN (festif vs zen) · règle reportée de la bible
A12: AMB | B12: Ambiance | C12: AMB-PRO | D12: PROFESSIONNEL | E12: tri (scoring) | F12: HEB·RES·ACT·ESP·POI | G12: AMB-PRO · PROFESSIONNEL
A13: AMB | B13: Ambiance | C13: AMB-FAM | D13: FAMILIAL | E13: tri (scoring) | F13: HEB·RES·ACT·ESP·POI | G13: AMB-FAM · FAMILIAL
A14: OR | B14: Esprit du séjour (client) | C14: OR-ZEN | D14: ZEN & BIEN-ÊTRE | E14: tri (scoring) | F14: HEB·RES·ACT·POI | G14: OR-ZEN · ZEN & BIEN-ÊTRE
A15: OR | B15: Esprit du séjour (client) | C15: OR-ROM | D15: ROMANTIQUE | E15: tri (scoring) | F15: HEB·RES·ACT·POI | G15: OR-ROM · ROMANTIQUE
A16: OR | B16: Esprit du séjour (client) | C16: OR-FAM | D16: FAMILIAL | E16: tri (scoring) | F16: HEB·RES·ACT·POI | G16: OR-FAM · FAMILIAL
A17: OR | B17: Esprit du séjour (client) | C17: OR-FES | D17: FESTIF | E17: tri (scoring) | F17: HEB·RES·ACT·POI | G17: OR-FES · FESTIF
A18: OR | B18: Esprit du séjour (client) | C18: OR-PRO | D18: PROFESSIONNEL | E18: tri (scoring) | F18: HEB·RES·ACT·POI | G18: OR-PRO · PROFESSIONNEL
A19: BG | B19: Budget | C19: BG1 | D19: Moins de 300 € | E19: filtre dur | F19: HEB·HB-COL·RES·ESP | G19: BG1 · Moins de 300 €
A20: BG | B20: Budget | C20: BG2 | D20: 300 – 500 € | E20: filtre dur | F20: HEB·HB-COL·RES·ESP | G20: BG2 · 300 – 500 €
A21: BG | B21: Budget | C21: BG3 | D21: 500 – 800 € | E21: filtre dur | F21: HEB·HB-COL·RES·ESP | G21: BG3 · 500 – 800 €
A22: BG | B22: Budget | C22: BG4 | D22: 800 – 1 200 € | E22: filtre dur | F22: HEB·HB-COL·RES·ESP | G22: BG4 · 800 – 1 200 €
A23: BG | B23: Budget | C23: BG5 | D23: 1 200 € et + | E23: filtre dur | F23: HEB·HB-COL·RES·ESP | G23: BG5 · 1 200 € et +
... A30: ACCÈS | B30: Type d'accès au lieu | C30: ACC-PRV | D30: Privatisable / sur demande | E30: filtre | F30: HEBERGEMENT·RESTAURANT·ACTIVITES·POI·SOIREE·ESPACES | G30: ACC-PRV · Privatisable / sur demande
A31: CONTRAINTE | B31: Contraintes opérationnelles | C31: NO_SMOKING | D31: Non-fumeur strict | E31: filtre dur | F31: HEB·RES·ESP | G31: NO_SMOKING · Non-fumeur strict | H31: Attribut lieu (moteur) · hors bible · pas d'équivalent client
A32: CONTRAINTE | B32: Contraintes opérationnelles | C32: NO_ALCOHOL_PUB | D32: Alcool en privé uniquement | E32: filtre dur | F32: HEB·RES·ESP | G32: NO_ALCOHOL_PUB · Alcool en privé uniquement | H32: Attribut lieu : le lieu sert de l'alcool en privé uniquement (le client ne le voit pas en public).
A33: CONTRAINTE | B33: Contraintes opérationnelles | C33: NO_LATE_MUSIC | D33: Musique limitée après 23h | E33: filtre dur | F33: HEB·RES·ESP | G33: NO_LATE_MUSIC · Musique limitée après 23h | H33: Attribut lieu (moteur) · hors bible · contrainte sonore
A34: CONTRAINTE | B34: Contraintes opérationnelles | C34: NPH | D34: Politique « no photo » | E34: filtre dur | F34: HEB·RES·ESP | G34: NPH · Politique « no photo » | H34: Attribut lieu (moteur) · hors bible · politique discrétion
A35: CONTRAINTE | B35: Contraintes opérationnelles | C35: NEIGH_SENSITIVE | D35: Voisinage sensible | E35: filtre dur | F35: HEB·RES·ESP | G35: NEIGH_SENSITIVE · Voisinage sensible | H35: Attribut lieu (moteur) · hors bible · contrainte voisinage
A36: CONTRAINTE | B36: Contraintes opérationnelles | C36: ACC_PMR | D36: Accès PMR / Handicap | E36: filtre dur | F36: HEB·RES·ESP | G36: ACC_PMR · Accès PMR / Handicap | H36: Attribut lieu (moteur) · hors bible · accessibilité PMR (candidat filtre futur)
A37: USAGE_EVT | B37: Usages événementiels | C37: ANNIV_FAM | D37: Anniversaire familial | E37: filtre | F37: HEB·ESP·EVT | G37: ANNIV_FAM · Anniversaire familial | H37: EV-AFA · Anniversaire familial (client)
A38: USAGE_EVT | B38: Usages événementiels | C38: ANNIV_FES | D38: Anniversaire festif | E38: filtre | F38: HEB·ESP·EVT | G38: ANNIV_FES · Anniversaire festif | H38: EV-AFE · Anniversaire festif (client)
A39: USAGE_EVT | B39: Usages événementiels | C39: ART_EVT | D39: Événement artistique | E39: filtre | F39: HEB·ESP·EVT | G39: ART_EVT · Événement artistique | H39: EV-AUT · cas par cas (pas de standard)
A40: USAGE_EVT | B40: Usages événementiels | C40: COCKTAIL | D40: Cocktail & réception | E40: filtre | F40: HEB·ESP·EVT | G40: COCKTAIL · Cocktail & réception | H40: EV-NET · Networking (back-office)
A41: USAGE_EVT | B41: Usages événementiels | C41: COHESION | D41: Cohésion d'équipe | E41: filtre | F41: HEB·ESP·EVT | G41: COHESION · Cohésion d'équipe | H41: EV-SEM · Séminaire (back-office)
A42: USAGE_EVT | B42: Usages événementiels | C42: DEFILE | D42: Défilé / présentation | E42: filtre | F42: HEB·ESP·EVT | G42: DEFILE · Défilé / présentation | H42: EV-AUT · cas par cas
... A55: USAGE_EVT | B55: Usages événementiels | C55: TOURNAGE | D55: Tournage & production | E55: filtre | F55: HEB·ESP·EVT | G55: TOURNAGE · Tournage & production | H55: EV-AUT · cas par cas
A56: CANAL | B56: Canaux de réservation | C56: DIRECT | D56: Direct | E56: info | F56: TOUS | G56: DIRECT · Direct
A57: CANAL | B57: Canaux de réservation | C57: BOOKING | D57: Booking.com | E57: info | F57: TOUS | G57: BOOKING · Booking.com
A58: CANAL | B58: Canaux de réservation | C58: AIRBNB | D58: Airbnb | E58: info | F58: TOUS | G58: AIRBNB · Airbnb
...

Sheet MATCHING
A1: 🎯 MATCHING · table remappée sur 🔖 CODES DE RÉFÉRENCE + 🌐 PARCOURS WEB · spécification d'ENTRÉE du futur MOTEUR · tags nus · codes manquants = ⚠ à créer
A2: FAMILLE | B2: CODE CLIENT | C2: LIBELLÉ | D2: TYPE | E2: SLOT / ÉTAPE | F2: FILTRE DUR (élimine) | G2: TAGS DE TRI (scoring · nus) | H2: RÈGLE MÉTIER | I2: Δ vs V1 / NOTE
A3: ═══ ÉTAPE 1 · CONFIGURATION DU SÉJOUR ═══
A4: COMPOSITION | B4: « pour N » | C4: Taille du groupe | D4: filtre dur + tri | E4: 1.2 composition | F4: capacité ≥ N | G4: PUB-SOL / PUB-CPL / PUB-FAM / PUB-GRP (selon compo) | H4: Dérive TV-SOL(1)/TV-CPL(2)/TV-GRP(≥3). PUB-GRP si N≥3. nb_enfants>0 → PUB-FAM + ouvre slot 2.9. | I4: Δ PUB-GRP conditionné au seuil N≥3 (V1: appliqué quel que soit N).
A5: OR · esprit | B5: OR-ZEN | C5: ZEN & BIEN-ÊTRE | D5: tri (scoring global) | E5: 1.4 esprit | F5: — | G5: AMB-ZEN · SPA · HAM_TRA · YOG_OUT | H5: Single-select obligatoire. Boost sur tout le séjour (HEB·RES·ACT·POI). | I5: Δ amenities passées en ⚠ à créer (pas d'attribut lieu dans la bible).
A6: OR · esprit | B6: OR-ROM | C6: ROMANTIQUE | D6: tri (scoring global) | E6: 1.4 esprit | F6: — | G6: AMB-ROM · PUB-CPL · TER · BAR_RTP | H6: Boost global.
A7: OR · esprit | B7: OR-FAM | C7: FAMILIAL | D7: tri (scoring global) | E7: 1.4 esprit | F7: — | G7: AMB-FAM · PUB-FAM · KD-CLB · BAB | H7: Boost global.
A8: OR · esprit | B8: OR-FES | C8: FESTIF | D8: tri (scoring global) | E8: 1.4 esprit | F8: — | G8: AMB-FES · PUB-GRP · DJ · CLU · POO_CLU | H8: Boost global. ⚠ AMB-FES ✕ AMB-ZEN incompatibles (règle bible) → pénalité croisée.
A9: OR · esprit | B9: OR-PRO | C9: PROFESSIONNEL | D9: tri (scoring global) | E9: 1.4 esprit | F9: — | G9: AMB-PRO · PUB-PRO | H9: Boost global.
A10: HB · héberg. | B10: HB-HOT | C10: HOTEL & RESORT | D10: filtre (type) | E10: 1.5.2 atmosphère | F10: type hébergement = HB-HOT | G10: ST-* · AMB-* (selon OR) | H10: Single-select. N'apparaît que si prise en charge héberg. = OUI. | I10: Δ 6 codes complets (V1: 1 seul « HB-HOT… »).
A11: HB · héberg. | B11: HB-INC | C11: INCONTOURNABLE | D11: filtre (type) | E11: 1.5.2 | F11: type hébergement = HB-INC | G11: ST-* · AMB-* (selon OR) | H11: Single-select.
A12: HB · héberg. | B12: HB-RIA | C12: RIAD & PATRIMOINE | D12: filtre (type) | E12: 1.5.2 | F12: type hébergement = HB-RIA | G12: ST-* · AMB-* (selon OR) | H12: Single-select.
A13: HB · héberg. | B13: HB-COL | C13: COLLECTION PRIVÉE | D13: filtre (type) | E13: 1.5.2 | F13: type hébergement = HB-COL | G13: ST-* · AMB-* (selon OR) | H13: Single-select.
A14: HB · héberg. | B14: HB-NAT | C14: NATURE & HORIZON | D14: filtre (type) | E14: 1.5.2 | F14: type hébergement = HB-NAT | G14: ST-* · AMB-* (selon OR) | H14: Single-select.
A15: HB · héberg. | B15: HB-SUR | C15: SUR MESURE ABSOLU | D15: filtre (combinaison) | E15: 1.5.2 | F15: combinaison ≥ 2 types d'hébergement | G15: ST-SIG · ST-ULT · ACC-PRV | H15: Mode multi-lieux (ex : riad médina + camp désert) composé par SOLY. N'est PAS un 6e type. · IMPOSE automatiquement BG-LIBRE (le client ne choisit pas de tranche BG1–BG5).
A16: BG · budget | B16: BG1 | C16: Moins de 300 € | D16: filtre dur | E16: 1.5.3 | F16: prix/nuit/chambre ≤ 300 € | G16: — | H16: Prix/nuit/chambre.
A17: BG · budget | B17: BG2 | C17: 300 – 500 € | D17: filtre dur | E17: 1.5.3 | F17: 300 < prix ≤ 500 | G17: — | H17: Prix/nuit/chambre.
A18: BG · budget | B18: BG3 | C18: 500 – 800 € | D18: filtre dur | E18: 1.5.3 | F18: 500 < prix ≤ 800 | G18: — | H18: Prix/nuit/chambre.
A19: BG · budget | B19: BG4 | C19: 800 – 1 200 € | D19: filtre dur | E19: 1.5.3 | F19: 800 < prix ≤ 1 200 | G19: — | H19: Prix/nuit/chambre.
A20: BG · budget | B20: BG5 | C20: 1 200 € et + | D20: filtre dur | E20: 1.5.3 | F20: prix/nuit/chambre ≥ 1 200 € | G20: ST-SIG · ST-ULT | H20: Prix/nuit/chambre.
A21: BG · budget | B21: BG-LIBRE | C21: SUR MESURE | D21: tri SEULEMENT | E21: 1.5.3 | F21: AUCUNE élimination · disponible UNIQUEMENT si HB-SUR | G21: ST-SIG · ST-ULT · ACC-PRV | H21: RÉSERVÉ à HB-SUR : jamais croisé avec un hébergement classique (HB-HOT/INC/RIA/COL/NAT). Sous HB-SUR, aucun filtre budget — SOLY compose le multi-lieux. Boost premium léger. | I21: Δ RÈGLE — BG-LIBRE ⟺ HB-SUR (couplage exclusif). Classiques → BG1–BG5 obligatoire. Anti-set-vide géré dans le chemin HB-SUR.
A22: ═══ ÉTAPE 2 · VOTRE EXPÉRIENCE ═══
A23: EV · événement | B23: EV-DEM | C23: DEMANDE EN MARIAGE | D23: filtre + tri + pack | E23: 2.1.1 | F23: usage = DEM_MAR · exactement 2 adultes | G23: AMB-ROM · ACC-PRV | H23: Cas exception (pas de mini 5). Déverse 2 PACKS CRM (fermés). Pack injecte SE-/EVT-/EP- via moteur.
A24: EV · événement | B24: EV-AFE | C24: ANNIVERSAIRE FESTIF | D24: filtre + tri + pack | E24: 2.1.1 | F24: usage = ANNIV_FES · ≥ 5 adultes (obligatoire · blocage dur) | G24: AMB-FES | H24: Déverse 2 PACKS CRM. | I24: Δ ajouté (split anniversaire V86).
A25: EV · événement | B25: EV-AFA | C25: ANNIVERSAIRE FAMILIAL | D25: filtre + tri + pack | E25: 2.1.1 | F25: usage = ANNIV_FAM · ≥ 5 adultes (obligatoire · blocage dur) | G25: AMB-FAM | H25: SEUL EV ouvrant le choix du nb d'enfants. Déverse 2 PACKS CRM. | I25: Δ ajouté (split V86).
A26: EV · événement | B26: EV-EVJF | C26: EVJF | D26: filtre + tri + pack | E26: 2.1.1 | F26: usage = EVJF · ≥ 5 adultes (obligatoire · blocage dur) | G26: AMB-FES | H26: Déverse 2 PACKS CRM.
A27: EV · événement | B27: EV-EVG | C27: EVG | D27: filtre + tri + pack | E27: 2.1.1 | F27: usage = EVG · ≥ 5 adultes (obligatoire · blocage dur) | G27: AMB-FES | H27: Déverse 2 PACKS CRM. | I27: Δ ajouté.
A28: EV · événement | B28: EV-AUT | C28: AUTRE | D28: filtre (libre) | E28: 2.1.1 | F28: usage libre (champ « à décrire ») | G28: — | H28: Pas de pack CRM. SOLY Assistance 24h. Conseiller puise biblio interne (EV-SEM/GALA/DES/DIN/NET/BAB/MAR/BAP/FIA/ANV/RET/REU/VOW). Parcours non bloqué. EV-ANN = catégorie parente, pas un choix terminal.
A29: EV · règle | B29: — | C29: Règle moteur quota | D29: règle | E29: 2.1.1 | F29: — | G29: — | H29: IF nb_adultes_étape1 < 5 (hors EV-DEM) → PACK INDISPONIBLE (blocage dur) · événement masqué/désactivé · message « Événement accessible à partir de 5 participants ». SEULE EXCEPTION : EV-DEM = 2 adultes.
A30: AU · matinée | B30: AU-DES | C30: DÉSERT & HORIZONS | D30: filtre + tri | E30: 2.4 matinée | F30: slot = matinée | G30: POI-VUE · QUA · BGY · DRM · AST | H30: Multi-select.
A31: AU · matinée | B31: AU-SPO | C31: SPORT & ÉNERGIE | D31: filtre + tri | E31: 2.4 matinée | F31: slot = matinée | G31: AU-SPO · YOG_OUT | H31: Multi-select. | I31: Δ ajouté (absent V1).
A32: AU · matinée | B32: AU-CUL | C32: CULTURE & IMMERSION | D32: filtre + tri | E32: 2.4 matinée | F32: slot = matinée | G32: AMB-ZEN · POI-VIS · POI-IMM | H32: Multi-select.
A33: AU · matinée | B33: AU-BIE | C33: BIEN-ÊTRE & RELAXATION | D33: filtre + tri | E33: 2.4 matinée | F33: slot = matinée | G33: AMB-ZEN · SPA · HAM_TRA · YOG_OUT | H33: Multi-select.
A34: AU · matinée | B34: AU-ELI | C34: ÉLITE & SIGNATURE | D34: filtre + tri | E34: 2.4 matinée | F34: slot = matinée | G34: ST-SIG · ST-ULT · AU-ELI | H34: Multi-select. | I34: Δ ajouté.
A35: AU · matinée | B35: AU-EXC | C35: EXCURSION À LA JOURNÉE | D35: filtre + tri · EXCLUSIF | E35: 2.4 matinée | F35: slot = matinée · DÉSACTIVE 2.5 + 2.6 | G35: AGA · 4X4 | H35: Exclusif : ne restent accessibles que dîner (2.7) + soirée (2.8). | I35: Δ règle exclusivité précisée.
A36: RA-D · déjeuner | B36: RA-DBR | C36: Brunch & art de vivre | D36: filtre + tri | E36: 2.5 déjeuner | F36: slot = déjeuner | G36: TER · BAR_POO | H36: Multi-select · RESTAURANT.
A37: RA-D · déjeuner | B37: RA-DLE | C37: Déjeuner léger & élégant | D37: filtre + tri | E37: 2.5 | F37: slot = déjeuner | G37: ST-SIG | H37: Multi-select. | I37: Δ ajouté.
A38: RA-D · déjeuner | B38: RA-DMA | C38: Déjeuner marocain d'exception | D38: filtre + tri | E38: 2.5 | F38: slot = déjeuner | G38: AMB-ZEN · RA-DMA | H38: Multi-select.
A39: RA-D · déjeuner | B39: RA-DPO | C39: Poolside & Lifestyle | D39: filtre + tri | E39: 2.5 | F39: slot = déjeuner | G39: POO_CLU · BCH_CLU · BAR_POO | H39: Multi-select.
A40: RA-D · déjeuner | B40: RA-DNA | C40: Nature & Évasion | D40: filtre + tri | E40: 2.5 | F40: slot = déjeuner | G40: POI-VUE · TER | H40: Multi-select. | I40: Δ ajouté.
...

Sheet MOTEUR
A1: ⚙️ MOTEUR · spécification de calcul SOLÝVENTS — séquencée sur le 🌐 PARCOURS WEB (Étapes 1→4) · V2
A2: 📜 DOCTRINE · Le moteur suit le déroulé du parcours web. BLOC 0 (hors parcours) pré-qualifie chaque prestataire à l'onboarding (note intrinsèque → cloches LVL). Puis, à mesure que le client avance, le moteur applique les FILTRES DURS (éliminent) et le TRI (points, n'éliminent jamais) propres à chaque étape. Cellules JAUNES = seuls paramètres éditables.
A3: PIPELINE ▸ BLOC 0 Note intrinsèque /5 → cloches LVL │ ÉTAPE 1 filtres cadrage + tri esprit → ÉTAPE 2 filtres expériences + tri + packs EV → ÉTAPE 3 transport/sécurité/devis → ÉTAPE 4 classement final (note × coef NPS + Σ tri) + honoraires SOLÝ
A5: ═══ BLOC 0 · PRÉ-QUALIFICATION PRESTATAIRE (onboarding · hors parcours client) → note intrinsèque /5 & cloches LVL ═══
A6: Chaque score est noté 0–5 par le moteur à partir de la colonne source de la fiche. Note finale = Σ(score × poids)/100 (sur l'échelle 0–5 car Σ poids = 100). Les poids (jaune) sont éditables. Cette note est indépendante de la requête client — elle est calculée une fois, à l'onboarding.
A7: SCORE | B7: LIBELLÉ | C7: SOURCE (fiche / bible) | D7: RÈGLE DE NOTATION 0–5 | E7: ÉCHELLE | F7: POIDS % | G7: DÉTAIL / BARÈME INDICATIF
A8: M1 | B8: STANDING | C8: Col. STANDING (ST) · bible ST-PRE/SIG/ULT | D8: Mappage standing → note | E8: 0–5 | F8: 15 | G8: ST-ULT=5 · ST-SIG=4 · ST-PRE=3 · non renseigné=2
A9: M2 | B9: RATINGS plateformes | C9: Col. PLATEFORMES (RATING) · Google/Trip/Booking/Airbnb | D9: Moyenne pondérée des notes normalisées /5 (Booking /10 → /5), pondérée par nb d'avis (log) | E9: 0–5 | F9: 15 | G9: note_norm × min(1 ; log10(1+avis)/3) · multi-plateformes = moyenne
A10: M3 | B10: LABELS & DISTINCTIONS | C10: Bible LABEL-* (Relais&Châteaux, Michelin Key, Virtuoso, LHW…) | D10: +1 par label majeur, plafonné à 5 | E10: 0–5 | F10: 10 | G10: 0 label=0 · 1=2 · 2=3,5 · 3=4,5 · 4+=5
A11: M4 | B11: ANCIENNETÉ / RÉPUTATION | C11: Col. ANCIENNETÉ (ANC) · bible ANC-INST/ANC-NEW | D11: Institution = valeur sûre ; nouveau spot = potentiel | E11: 0–5 | F11: 6 | G11: ANC-INST=5 · standard=3 · ANC-NEW=3 (bonus découverte traité étape 4)
A12: M5 | B12: CLARTÉ DU POSITIONNEMENT | C12: Col. ATMOSPHÈRE (AMB) + ESPRIT (OR) | D12: Cohérence : AMB renseignée et non contradictoire | E12: 0–5 | F12: 6 | G12: AMB nette=5 · AMB générique=3 · conflit AMB-FES×AMB-ZEN=1
A13: M6 | B13: ÉQUIPEMENTS & SERVICES | C13: MASTER_TAGS ÉQUIPEMENT (spa, rooftop, pool club, DJ, terrasse…) | D13: Densité d'équipements distinctifs détectés sur la fiche | E13: 0–5 | F13: 10 | G13: 0 tag=1 · 1-2=3 · 3-4=4 · 5+=5
A14: M7 | B14: FAMILLE / ENFANTS | C14: Col. KD (KD-KFR/CLB/PIS/ACT) | D14: Couverture des équipements enfants (neutre si lieu non familial) | E14: 0–5 | F14: 4 | G14: aucun=2,5(neutre) · KD-KFR=3,5 · +CLB/PIS/ACT=+0,5 chacun (max 5)
A15: M8 | B15: ACCÈS & PRIVATISATION | C15: Col. TYPE D'ACCÈS (ACC) · ACC-PRV / privatisable | D15: Capacité à offrir de l'exclusivité | E15: 0–5 | F15: 6 | G15: ACC-PRV=5 · ACC-CLI=3 · ACC-PUB seul=2
A16: M9 | B16: COUVERTURE PUBLICS | C16: Col. PUBLIC (PUB-*) | D16: Largeur des publics adressés (sans diluer le positionnement) | E16: 0–5 | F16: 4 | G16: 1 public=3 · 2-3=4 · 4+=5 · incohérent=2
A17: M10 | B17: DIGITALISATION / PRÉSENCE | C17: Cols. NIVEAU DIGITAL, SITE, INSTA, réseaux | D17: Présence en ligne actionnable | E17: 0–5 | F17: 3 | G17: Élevé+site+réseaux=5 · moyen=3 · faible/à compléter=1
A18: M11 | B18: CONFORMITÉ RÉGLEMENTAIRE | C18: Cols. AUTORISATION, CLASSEMENT OFFICIEL (Maroc) | D18: Sécurité juridique du référencement | E18: 0–5 | F18: 4 | G18: conforme & classé=5 · en cours=3 · NC=1
A19: M12 | B19: COMMERCIAL / PARTENARIAT | C19: Cols. CONVENTION SIGNÉE, COMMISSION, STATUT CONTACT | D19: Solidité de la relation SOLÝ | E19: 0–5 | F19: 5 | G19: convention signée=5 · en négociation=3 · non contacté=1
... A21: M14 | B21: SCORE SUR-MESURE | C21: Bible SC · SCORE_SUR_MESURE (🆕) · capacité à privatiser/composer | D21: Aptitude à fermer un lieu / composer multi-lieux (HB-SUR) | E21: 0–5 | F21: 8 | G21: privatisation totale + multi-lieux=5 · privatisable partiel=3 · non=1
A22: TOTAL PONDÉRATIONS (doit faire 100) | F22: =SUM(F8:F21) -> 100
A24: ▸ EXEMPLE DE CALCUL · fiche fictive « Riad Signature » (modifiez les notes 0–5 en colonne F pour tester le moteur)
A25: SCORE | B25: LIBELLÉ | F25: NOTE 0–5 | G25: CONTRIB = note × poids /100
A26: =A8 -> M1 | B26: =B8 -> STANDING | F26: 5 | G26: =F26*F8/100 -> 0.75
A27: =A9 -> M2 | B27: =B9 -> RATINGS plateformes | F27: 4 | G27: =F27*F9/100 -> 0.6
A28: =A10 -> M3 | B28: =B10 -> LABELS & DISTINCTIONS | F28: 3.5 | G28: =F28*F10/100 -> 0.35
A29: =A11 -> M4 | B29: =B11 -> ANCIENNETÉ / RÉPUTATION | F29: 5 | G29: =F29*F11/100 -> 0.3
A30: =A12 -> M5 | B30: =B12 -> CLARTÉ DU POSITIONNEMENT | F30: 5 | G30: =F30*F12/100 -> 0.3
A31: =A13 -> M6 | B31: =B13 -> ÉQUIPEMENTS & SERVICES | F31: 4 | G31: =F31*F13/100 -> 0.4
A32: =A14 -> M7 | B32: =B14 -> FAMILLE / ENFANTS | F32: 2.5 | G32: =F32*F14/100 -> 0.1
A33: =A15 -> M8 | B33: =B15 -> ACCÈS & PRIVATISATION | F33: 5 | G33: =F33*F15/100 -> 0.3
A34: =A16 -> M9 | B34: =B16 -> COUVERTURE PUBLICS | F34: 4 | G34: =F34*F16/100 -> 0.16
A35: =A17 -> M10 | B35: =B17 -> DIGITALISATION / PRÉSENCE | F35: 3 | G35: =F35*F17/100 -> 0.09
A36: =A18 -> M11 | B36: =B18 -> CONFORMITÉ RÉGLEMENTAIRE | F36: 3 | G36: =F36*F18/100 -> 0.12
A37: =A19 -> M12 | B37: =B19 -> COMMERCIAL / PARTENARIAT | F37: 5 | G37: =F37*F19/100 -> 0.25
... A39: =A21 -> M14 | B39: =B21 -> SCORE SUR-MESURE | F39: 3 | G39: =F39*F21/100 -> 0.24
A40: NOTE INTRINSÈQUE FINALE (Σ contributions · échelle 0–5) | G40: =SUM(G26:G39) -> 4.16
A41: → QUALIFICATION LVL (cloches) dérivée automatiquement | G41: {=IFS(G40<=2,"LVL-1 · 🔔",G40<=3.5,"LVL-2 · 🔔🔔",G40<=4,"LVL-3 · 🔔🔔🔔",G40<=4.5,"LVL-4 · 🔔🔔🔔🔔",TRUE,"LVL-5 · 🔔🔔🔔🔔🔔")} -> LVL-4 · 🔔🔔🔔🔔
A43: ═══ BANDES LVL · LES CLOCHES (mapping note finale → qualification · repris de la bible) ═══
A44: CODE | B44: LIBELLÉ | C44: NOTE FINALE | D44: SENS | G44: COMMENTAIRE MOTEUR
A45: LVL-1 | B45: 🔔 UNE CLOCHE | C45: 0 – 2,0 | D45: Hors standard / non retenu | G45: Sort de la matrice de recommandation
...

Sheet SCORING_RULES
A1: ⚙️ SCORING_RULES · pondération des tags de TRI · paramètre éditable du MOTEUR · V1
A2: 📜 DOCTRINE · Cet onglet sort les POIDS du code : chaque tag de tri reçoit un SCORE (points) que le moteur additionne en phase de tri (jamais d'élimination). Modifier un score ici = re-régler le moteur sans toucher au développement. Barème de référence : voir MOTEUR · Section B (AMB exact = +20, esprit OR = +15, standing = +10/15…).
A3: 🔗 Colonnes FAMILLE / TAG / LIBELLÉ / TYPE = tirées par formule de MASTER_TAGS (auto-alignées sur la bible : un tag de tri ajouté à la bible apparaît ici). Colonne SCORE (jaune) = seul paramètre à saisir, laissé à blanc en V1.
H4: ⚙️ BARÈME DE TRI · source unique des poids (éditable) — repris de MOTEUR Section B
A5: FAMILLE | B5: TAG | C5: LIBELLÉ | D5: TYPE MATCHING | E5: SCORE (pts) | H5: CLÉ (tag ou famille) | I5: POINTS | J5: RÉFÉRENCE MOTEUR
A6: {=_xlws.FILTER(MASTER_TAGS!A3:A221,ISNUMBER(SEARCH("tri",MASTER_TAGS!E3:E221))*ISERROR(SEARCH("pas de",MASTER_TAGS!E3:E221)))} -> #NAME? | B6: {=_xlws.FILTER(MASTER_TAGS!C3:E221,ISNUMBER(SEARCH("tri",MASTER_TAGS!E3:E221))*ISERROR(SEARCH("pas de",MASTER_TAGS!E3:E221)))} -> #NAME? | E6: =XLOOKUP($B6,$H$6:$H$25,$I$6:$I$25,XLOOKUP($A6,$H$6:$H$25,$I$6:$I$25,0)) -> #NAME? | H6: AMB | I6: 20 | J6: T1 · Ambiance exacte — cœur du tri
E7: =XLOOKUP($B7,$H$6:$H$25,$I$6:$I$25,XLOOKUP($A7,$H$6:$H$25,$I$6:$I$25,0)) -> 0 | H7: OR | I7: 15 | J7: T2 · Esprit du séjour
E8: =XLOOKUP($B8,$H$6:$H$25,$I$6:$I$25,XLOOKUP($A8,$H$6:$H$25,$I$6:$I$25,0)) -> 0 | H8: ST-ULT | I8: 15 | J8: T3 · Standing ultra exclusif
E9: =XLOOKUP($B9,$H$6:$H$25,$I$6:$I$25,XLOOKUP($A9,$H$6:$H$25,$I$6:$I$25,0)) -> 0 | H9: ST-SIG | I9: 10 | J9: T3 · Standing signature
E10: =XLOOKUP($B10,$H$6:$H$25,$I$6:$I$25,XLOOKUP($A10,$H$6:$H$25,$I$6:$I$25,0)) -> 0 | H10: ST-PRE | I10: 5 | J10: T3 · Standing premium (interpolé)
E11: =XLOOKUP($B11,$H$6:$H$25,$I$6:$I$25,XLOOKUP($A11,$H$6:$H$25,$I$6:$I$25,0)) -> 0 | H11: LVL-5 | I11: 20 | J11: T9 · Cloches — tête de liste
E12: =XLOOKUP($B12,$H$6:$H$25,$I$6:$I$25,XLOOKUP($A12,$H$6:$H$25,$I$6:$I$25,0)) -> 0 | H12: LVL-4 | I12: 15 | J12: T9 · Cloches
E13: =XLOOKUP($B13,$H$6:$H$25,$I$6:$I$25,XLOOKUP($A13,$H$6:$H$25,$I$6:$I$25,0)) -> 0 | H13: LVL-3 | I13: 10 | J13: T9 · Cloches
E14: =XLOOKUP($B14,$H$6:$H$25,$I$6:$I$25,XLOOKUP($A14,$H$6:$H$25,$I$6:$I$25,0)) -> 0 | H14: LVL-2 | I14: 5 | J14: T9 · Cloches
E15: =XLOOKUP($B15,$H$6:$H$25,$I$6:$I$25,XLOOKUP($A15,$H$6:$H$25,$I$6:$I$25,0)) -> 0 | H15: LVL-1 | I15: 0 | J15: T9 · Hors standard
E16: =XLOOKUP($B16,$H$6:$H$25,$I$6:$I$25,XLOOKUP($A16,$H$6:$H$25,$I$6:$I$25,0)) -> 0 | H16: ÉQUIPEMENT | I16: 12 | J16: T5 · Tag équipement ciblé (plafond +36)
E17: =XLOOKUP($B17,$H$6:$H$25,$I$6:$I$25,XLOOKUP($A17,$H$6:$H$25,$I$6:$I$25,0)) -> 0 | H17: PUBLIC | I17: 8 | J17: T4 · Match public
E18: =XLOOKUP($B18,$H$6:$H$25,$I$6:$I$25,XLOOKUP($A18,$H$6:$H$25,$I$6:$I$25,0)) -> 0 | H18: POI | I18: 8 | J18: T6 · Catégorie POI demandée
... E25: =XLOOKUP($B25,$H$6:$H$25,$I$6:$I$25,XLOOKUP($A25,$H$6:$H$25,$I$6:$I$25,0)) -> 0 | H25: KD | I25: 8 | J25: Équipement enfants du lieu
E26: =XLOOKUP($B26,$H$6:$H$25,$I$6:$I$25,XLOOKUP($A26,$H$6:$H$25,$I$6:$I$25,0)) -> 0
E27: =XLOOKUP($B27,$H$6:$H$25,$I$6:$I$25,XLOOKUP($A27,$H$6:$H$25,$I$6:$I$25,0)) -> 0
E28: =XLOOKUP($B28,$H$6:$H$25,$I$6:$I$25,XLOOKUP($A28,$H$6:$H$25,$I$6:$I$25,0)) -> 0
E29: =XLOOKUP($B29,$H$6:$H$25,$I$6:$I$25,XLOOKUP($A29,$H$6:$H$25,$I$6:$I$25,0)) -> 0
E30: =XLOOKUP($B30,$H$6:$H$25,$I$6:$I$25,XLOOKUP($A30,$H$6:$H$25,$I$6:$I$25,0)) -> 0
E31: =XLOOKUP($B31,$H$6:$H$25,$I$6:$I$25,XLOOKUP($A31,$H$6:$H$25,$I$6:$I$25,0)) -> 0
E32: =XLOOKUP($B32,$H$6:$H$25,$I$6:$I$25,XLOOKUP($A32,$H$6:$H$25,$I$6:$I$25,0)) -> 0
E33: =XLOOKUP($B33,$H$6:$H$25,$I$6:$I$25,XLOOKUP($A33,$H$6:$H$25,$I$6:$I$25,0)) -> 0
E34: =XLOOKUP($B34,$H$6:$H$25,$I$6:$I$25,XLOOKUP($A34,$H$6:$H$25,$I$6:$I$25,0)) -> 0
E35: =XLOOKUP($B35,$H$6:$H$25,$I$6:$I$25,XLOOKUP($A35,$H$6:$H$25,$I$6:$I$25,0)) -> 0
E36: =XLOOKUP($B36,$H$6:$H$25,$I$6:$I$25,XLOOKUP($A36,$H$6:$H$25,$I$6:$I$25,0)) -> 0
E37: =XLOOKUP($B37,$H$6:$H$25,$I$6:$I$25,XLOOKUP($A37,$H$6:$H$25,$I$6:$I$25,0)) -> 0
... E93: =XLOOKUP($B93,$H$6:$H$25,$I$6:$I$25,XLOOKUP($A93,$H$6:$H$25,$I$6:$I$25,0)) -> 0

Sheet SOLY_RULES
A1: 🤖 SOLY_RULES · garde-fous de génération automatique des séjours SOLÝ · V1
A2: 📜 DOCTRINE · Règles non négociables que le moteur / l'IA SOLÝ doit respecter avant de proposer un séjour. Filtres durs = éliminent ; règles & garde-fous = encadrent ; pénalités = déclassent sans éliminer. Chaque règle pointe vers son onglet source.
A4: # | B4: RÈGLE | C4: TYPE | D4: PORTÉE / PARAMÈTRE | E4: SOURCE | F4: STATUT
A5: 1 | B5: Minimum 2 expériences par jour | C5: Composition | D5: ≥ 2 expériences / jour (hors hébergement) | E5: SOLY_RULES (ordre slots ci-dessous) · PARCOURS 2.2 | F5: ✓ Actif
A6: 2 | B6: Pas de double réservation | C6: Composition | D6: 1 prestataire / créneau max par jour | E6: SOLY_RULES (ordre slots ci-dessous) | F6: ✓ Actif
A7: 3 | B7: Respect des filtres alimentaires | C7: Filtre dur + info | D7: RG-VEG → exige VENUE_VEGETARIAN ; RG-ALG = signalement (non bloquant) | E7: MATCHING F5 · MASTER_TAGS | F7: ⚠ À instrumenter (attribut lieu)
A8: 4 | B8: Respect du budget | C8: Filtre dur | D8: BG1–BG5 = bande prix/nuit (hébergement classique) ; BG-LIBRE = aucun filtre, RÉSERVÉ à HB-SUR (couplage exclusif — anti set-vide) | E8: MATCHING F2 | F8: ✓ Actif
A9: 5 | B9: Respect du nombre de participants | C9: Filtre dur | D9: capacité ≥ N ; PUB-GRP exigé si N ≥ 3 | E9: MATCHING F1 | F9: ✓ Actif
A10: 6 | B10: Respect du type d'hébergement | C10: Filtre dur | D10: HB-* single-select ; HB-SUR = combinaison ≥ 2 types (multi-lieux) → impose BG-LIBRE | E10: MATCHING F3 | F10: ✓ Actif
A11: 7 | B11: Respect du slot / créneau | C11: Filtre dur | D11: la fiche doit servir le slot demandé (matinée…soirée) | E11: MATCHING F4 | F11: ✓ Actif
A12: 8 | B12: Quota événement ≥ 5 participants (blocage dur) | C12: Filtre dur | D12: EV-* accessibles uniquement à ≥ 5 participants · SEULE EXCEPTION EV-DEM (demande en mariage = 2 adultes) · sous 5 (hors EV-DEM) → pack INDISPONIBLE, événement masqué/désactivé | E12: PARCOURS 2.1 · MATCHING · MOTEUR | F12: ✓ Actif
A13: 9 | B13: Exclusivité AU-EXC | C13: Règle composition | D13: excursion journée → désactive Déjeuner (2.5) + Après-midi (2.6) | E13: SOLY_RULES (ordre slots ci-dessous) · MATCHING | F13: ✓ Actif
A14: 10 | B14: Anti set-vide | C14: Garde-fou | D14: ne jamais renvoyer 0 résultat (Sur mesure, quota < 5, RG souples) | E14: MOTEUR · doctrine | F14: ✓ Actif
A15: 11 | B15: Le tri n'élimine jamais | C15: Principe moteur | D15: les tags de tri ré-ordonnent les fiches conformes, sans en exclure | E15: MOTEUR · Section B | F15: ✓ Actif
A16: 12 | B16: Incompatibilité AMB-FES × AMB-ZEN | C16: Pénalité | D16: −30 pts (déclasse, n'élimine pas) ; festif × zen | E16: MOTEUR P1 | F16: ✓ Actif
... A20: 16 | B20: Double codage hébergement | C20: Règle données | D20: Un lieu vendu à la nuit ET privatisable = 2 fiches distinctes, une par code applicable (ex : HOT/INC/RIA à la nuit + COL en privatisation ; chaque fiche = 1 ID contact unique). Valable sur tout le fichier + onglet HEBERGEMENT. | E20: HEBERGEMENT · REF_CODES | F20: ✓ Actif
A22: 🧩 ORDRE D'ASSEMBLAGE DES SLOTS · le moteur remplit chaque journée dans l'ordre de priorité croissante (repris de l'ex-onglet COMPOSITION_RULES)
A23: SLOT | B23: PRIORITÉ | C23: RÉF. PARCOURS
A24: MATINÉE | B24: 1 | C24: 2.4
A25: DÉJEUNER | B25: 2 | C25: 2.5
A26: APRÈS-MIDI | B26: 3 | C26: 2.6
A27: DÎNER | B27: 4 | C27: 2.7
A28: SOIRÉE | B28: 5 | C28: 2.8
A29: ENFANTS | B29: 6 | C29: 2.9

Sheet HONORAIRES_SOLY
A1: 💰 HONORAIRES_SOLY · rémunération SOLÝ = % par type de prestation réservée · V1
A2: 📜 DOCTRINE · SOLÝ facture un honoraire = un POURCENTAGE appliqué au montant réservé de chaque type de prestation (parcours Étape 4). Honoraire = Montant réservé HT × % SOLÝ. Le client paie : Σ montants réservés (étapes 1–3) + Σ honoraires SOLÝ. Les % (jaune) sont à définir par la direction.
A3: 🔗 Colonne MONTANT RÉSERVÉ = alimentée par le cumul du devis (étapes 1–3 du MOTEUR) · ici valeurs d'EXEMPLE à remplacer par le devis réel. Colonne % SOLÝ = barre tarifaire à saisir une fois.
A5: # | B5: TYPE DE PRESTATION | C5: CODES / FAMILLES CONCERNÉS (étape) | D5: MONTANT RÉSERVÉ HT (€) | E5: % HONORAIRE SOLÝ | F5: HONORAIRE SOLÝ (€)
A6: 1 | B6: Hôtel / Hébergement | C6: HB-* (Étape 1) | D6: 8000 | E6: 0.1 | F6: =IF($E6="","",D6*E6) -> 800
A7: 2 | B7: Événement à organiser | C7: EV-* + 2 PACKS CRM (Étape 2.1) | D7: 2000 | E7: 0.1 | F7: =IF($E7="","",D7*E7) -> 200
A8: 3 | B8: Événementiel | C8: EVT-* prestataires (DJ, traiteur, déco, fleuriste, photo…) (Étape 2.1) | D8: 1500 | E8: 0.1 | F8: =IF($E8="","",D8*E8) -> 150
A9: 4 | B9: Espace privatisé | C9: EP-* / ESP-TYPE espaces privatisables (Étape 2.1) | D9: 1000 | E9: 0.1 | F9: =IF($E9="","",D9*E9) -> 100
A10: 5 | B10: Activité | C10: Toutes expériences : AU-* · RA-D* · RA-N* · NL-* · POI · AK-* (Kids / Enfants) (Étape 2) | D10: 1200 | E10: 0.1 | F10: =IF($E10="","",D10*E10) -> 120
A11: 6 | B11: Transport | C11: TR-* (Étape 3) | D11: 500 | E11: 0.1 | F11: =IF($E11="","",D11*E11) -> 50
A12: 7 | B12: Sécurité | C12: SE-* privées (Étape 3) | D12: 250 | E12: 0.1 | F12: =IF($E12="","",D12*E12) -> 25
A13: TOTAL | B13: Séjour + honoraires | D13: =SUM(D6:D12) -> 14450 | E13: =IF(D13=0,"",F13/D13) -> 0.1 | F13: =SUM(F6:F12) -> 1445
A15: MONTANT TOTAL À PAYER PAR LE CLIENT (HT) | D15: =D13+F13 -> 15895

Sheet HEBERGEMENT
B1: IDENTITÉ & LOCALISATION · ✅ V1 vérifié (aligné 🔖 CODES DE RÉFÉRENCE) | M1: TARIFS (€/NUIT) | T1: COORDONNÉES & RÉSEAUX | AA1: NOTES | AB1: ATTRIBUTS RÉFÉRENTIEL SOLÝVENTS
A2: VILLE | B2: DESIGNATION | C2: ID CONTACT | D2: LIBELLÉ SOLÝVENTS | E2: CODE | F2: NOM | G2: CLASSEMENT (REF) | H2: BUDGET (BG) | I2: ADRESSE | J2: QUARTIER | K2: NBRE DE CH | L2: PRIVATISABLE | M2: CHAMBRE | N2: MINI SUITE | O2: SUITE | P2: SUITE AVEC PISCINE | Q2: VILLA – NB CH | R2: VILLA – TARIF (À PARTIR DE) | S2: NOTES | T2: TELEPHONE | U2: WHATSAPP | V2: EMAIL | W2: CONTACT DÉCISIONNAIRE | X2: SITE WEB | Y2: INSTAGRAM | Z2: FACEBOOK | AA2: NOTES CONTACT | AB2: STANDING (ST) | AC2: ATMOSPHÈRE (AMB) | AD2: ÉQUIP. ENFANTS (KD) | AE2: QUALIF · CLOCHE (LVL) | AF2: LABELS / DISTINCTIONS (LAB) | AG2: ESPRIT (OR) | AH2: PUBLIC | AI2: TYPE D'ACCÈS (ACC) | AJ2: USAGES ÉVÉNEMENTIELS
A3: MARRAKECH | B3: HEBERGEMENT | C3: H072 | D3: INCONTOURNABLE | E3: {=IFERROR(INDEX(REF_CODES!$B$8:$B$13,MATCH($D3,REF_CODES!$C$8:$C$13,0)),"")} -> HB-INC | F3: LES JARDINS DE LA KOUTOUBIA | G3: 5 ETOILES | H3: BG1 · Moins de 300 € | I3: 26 Rue De La Koutoubia, Médina | J3: Medina | K3: 108 | L3: NON | M3: 285 | N3: 465 | O3: 525 | P3: 725 | Q3: NA | R3: NA | S3: NA | T3: 212 5 24 38 8800 | U3: À compléter | V3: commercial@jardinskoutoubia.com | W3: à compléter | X3: https://www.lesjardinsdelakoutoubia.com | Y3: @jardinsdelakoutoubia | Z3: https://facebook.com/jardinsdelakoutoubia | AA3: Importé de HEBERGEMENT. Quartier : Medina · Site : https://www.lesjardinsdelakoutoubia.com | Coord. complétée(s) depuis annuaire : tél [Ancien statut: Importé] | AB3: ST-ULT · ULTRA EXCLUSIF | AC3: AMB-ROM · ROMANTIQUE | AD3: KD-KFR · KIDS FRIENDLY | AE3: LVL-3 · 🔔🔔🔔 TROIS CLOCHES | AF3: À qualifier (labels / distinctions) | AG3: OR-ROM · ROMANTIQUE | AH3: PUB-CPL · Couple | AI3: ACC-PUB | AJ3: Mariage, séminaire, privatisation
A4: MARRAKECH | B4: HEBERGEMENT | C4: H073 | D4: INCONTOURNABLE | E4: {=IFERROR(INDEX(REF_CODES!$B$8:$B$13,MATCH($D4,REF_CODES!$C$8:$C$13,0)),"")} -> HB-INC | F4: Es Saadi Marrakech Resort - Palace | G4: 5 ETOILES | H4: BG3 · 500 – 800 € | I4: Rue Ibrahim El Mazini Hivernage, L'Hivernage | J4: Hivernage | K4: 252 | L4: NON | M4: 367 | N4: 518 | O4: 647 | P4: NA | Q4: 1 ; 2 | R4: 1600 | S4: NA | T4: +212 524 337400 | U4: À compléter | V4: selfcoordination@essaadi.com · palace@essaadi.com | W4: Rania BAAMRI | X4: https://www.essaadi.com | Y4: @essaadimarrakech | Z4: https://facebook.com/essaadimarrakechresort | AA4: Importé de HEBERGEMENT. Quartier : Hivernage · Site : https://www.essaadi.com | Coord. complétée(s) depuis annuaire : tél [Ancien statut: Importé] | Villa(s) privatisable(s) déplacée(s) → HB-COL | AB4: ST-ULT · ULTRA EXCLUSIF | AC4: AMB-ROM · ROMANTIQUE | AD4: KD-CLB · KIDS CLUB | AE4: LVL-3 · 🔔🔔🔔 TROIS CLOCHES | AF4: À qualifier (labels / distinctions) | AG4: OR-PRO · PROFESSIONNEL | AH4: PUB-GRP · Groupe | AI4: ACC-PUB | AJ4: Très fort potentiel évènementiel
A5: MARRAKECH | B5: HEBERGEMENT | C5: H075 | D5: INCONTOURNABLE | E5: {=IFERROR(INDEX(REF_CODES!$B$8:$B$13,MATCH($D5,REF_CODES!$C$8:$C$13,0)),"")} -> HB-INC | F5: Hôtel & Ryads Barrière Le Naoura | G5: 5 ETOILES | H5: BG2 · 300 – 500 € | I5: Djebel Alakhdar - Bab Doukkala, Médina | J5: Hivernage | K5: 145 | L5: OUI | M5: 300 | N5: 400 | O5: 600 | P5: 900 | Q5: 1 ; 2 ; 3 ; 6 | R5: 1200 | S5: Villa 1 CH: 1200 · Villa 2 CH: 1800 · Villa 3 CH: 2500 · Villa 6 CH: 5000 | T5: 212524459000 | U5: À compléter | V5: reservation@groupebarriere.com | W5: à compléter | X5: https://www.hotelsbarriere.com/fr/marrakech/le-naoura.html | Y5: à compléter | Z5: https://facebook.com/hotelryadsbarrierelenaouramarrakech | AA5: Importé de HEBERGEMENT. Quartier : Hivernage · Site : https://www.hotelsbarriere.com/fr/marrakech/le-naoura.html | Coord. complétée(s) depuis annuaire : tél [Ancien statut: Importé] | Villa(s) privatisable(s) déplacée(s) → HB-COL | AB5: ST-ULT · ULTRA EXCLUSIF | AC5: AMB-ROM · ROMANTIQUE | AD5: KD-KFR · KIDS FRIENDLY | AE5: LVL-3 · 🔔🔔🔔 TROIS CLOCHES | AF5: À qualifier (labels / distinctions) | AG5: OR-ROM · ROMANTIQUE | AH5: PUB-CPL · Couple | AI5: ACC-PUB · ACC-PRV | AJ5: Mariage, séminaire, privatisation
A6: MARRAKECH | B6: HEBERGEMENT | C6: H026 | D6: HOTEL & RESORT | E6: {=IFERROR(INDEX(REF_CODES!$B$8:$B$13,MATCH($D6,REF_CODES!$C$8:$C$13,0)),"")} -> HB-HOT | F6: Park Hyatt Marrakech | G6: 5 ETOILES | H6: BG3 · 500 – 800 € | I6: Al Maaden Golf Resort | J6: Al Maaden | K6: 130 | L6: OUI | M6: 550 | N6: NA | O6: 700 | P6: NA | Q6: 1 ; 2 ; 3 | R6: 1800 | S6: Villa 1 CH: 1800 · Villa 2 CH: 3000 · Villa 3 CH: 4500 | T6: +212 7 75 75 75 61 / 212524441234 | U6: +212 775757561 (à confirmer) | V6: marrakech.park@hyatt.com | W6: Mme Fatim Zahra El Basri | X6: non trouvé | Y6: @parkhyattmarrakech | Z6: https://facebook.com/ParkHyattmarrakech | AA6: Coord. complétée(s) depuis annuaire : tél | Villa(s) privatisable(s) déplacée(s) → HB-COL | AB6: ST-ULT · ULTRA EXCLUSIF | AC6: AMB-ROM · ROMANTIQUE | AD6: KD-CLB · KIDS CLUB | AE6: LAB-VIRT · VIRTUOSO | AF6: LAB-VIRT · VIRTUOSO | AG6: OR-ROM · ROMANTIQUE | AH6: PUB-CPL · Couple | AI6: ACC-PUB · ACC-PRV | AJ6: Séminaires premium
A7: MARRAKECH | B7: HEBERGEMENT | C7: H004 | D7: INCONTOURNABLE | E7: {=IFERROR(INDEX(REF_CODES!$B$8:$B$13,MATCH($D7,REF_CODES!$C$8:$C$13,0)),"")} -> HB-INC | F7: The Oberoi Marrakech | G7: 5 ETOILES | H7: BG3 · 500 – 800 € | I7: BP 22788 - Route de Ouarzazate | J7: Route d'Ouarzazate | K7: 111 | L7: OUI | M7: 481 | N7: 750 | O7: 900 | P7: 1000 | Q7: 1 | R7: 1200 | S7: NA | T7: +212 525 08 15 15 / +212 664 77 66 31 / 212525081515 | U7: +212 664776631 (à confirmer) | V7: reservations@oberoigroup.com | W7: Mlle Fatima Ezahra El Idrissi | X7: https://www.oberoihotels.com/hotels-in-morocco-marrakech/ | Y7: @oberoimarrakech | Z7: NA | AA7: Coord. complétée(s) depuis annuaire : tél | Villa(s) privatisable(s) déplacée(s) → HB-COL | AB7: ST-ULT · ULTRA EXCLUSIF | AC7: AMB-ROM · ROMANTIQUE | AD7: KD-CLB · KIDS CLUB | AE7: LAB-VIRT · VIRTUOSO | AF7: LAB-VIRT · VIRTUOSO | AG7: OR-ROM · ROMANTIQUE | AH7: PUB-CPL · Couple | AI7: ACC-PUB · ACC-PRV | AJ7: Mariages destination
A8: MARRAKECH | B8: HEBERGEMENT | C8: H001 | D8: INCONTOURNABLE | E8: {=IFERROR(INDEX(REF_CODES!$B$8:$B$13,MATCH($D8,REF_CODES!$C$8:$C$13,0)),"")} -> HB-INC | F8: Royal Mansour Marrakech | G8: 5 ETOILES | H8: BG5 · 1 200 € et + | I8: Rue Abou Abbas El Sebti, Médina | J8: Hivernage | K8: 53 | L8: OUI | M8: 2200 | N8: 2800 | O8: 3500 | P8: NA | Q8: 1 ; 2 ; 3 ; 4 | R8: 1500 | S8: NA | T8: +212 529 80 80 80 / 212529808069 | U8: À compléter | V8: marrakech@royalmansour.com | W8: M. Ibensrhir (ibensrhir@royalmansour.com) | X8: https://www.royalmansour.com | Y8: @royalmansour | Z8: @royalmansourmarrakech | AA8: Domaine email corrigé (royalmansour.com) | Coord. complétée(s) depuis annuaire : tél [Ancien statut: Complété ✦] | Villa(s) privatisable(s) déplacée(s) → HB-COL | AB8: ST-ULT · ULTRA EXCLUSIF | AC8: AMB-ROM · ROMANTIQUE | AD8: KD-KFR · KIDS FRIENDLY | AE8: LAB-VIRT · VIRTUOSO · LAB-LHW · LEADING HOTELS OF THE WORLD | AF8: LAB-VIRT · VIRTUOSO · LAB-LHW · LEADING HOTELS OF THE WORLD | AG8: OR-ROM · ROMANTIQUE | AH8: PUB-CPL · Couple | AI8: ACC-PUB · ACC-PRV | AJ8: Mariages VIP, privatisations
A9: MARRAKECH | B9: HEBERGEMENT | C9: H006 | D9: INCONTOURNABLE | E9: {=IFERROR(INDEX(REF_CODES!$B$8:$B$13,MATCH($D9,REF_CODES!$C$8:$C$13,0)),"")} -> HB-INC | F9: Amanjena Resort | G9: 5 ETOILES | H9: BG4 · 800 – 1 200 € | I9: Km 12 Route de Ouarzazate P.O. Box 2405 | J9: Route d'Ouarzazate | K9: 40 | L9: OUI | M9: 837 | N9: 1100 | O9: 1500 | P9: 2000 | Q9: 1 | R9: 4000 | S9: NA | T9: +212 524 39 90 00 | U9: À compléter | V9: amanjena@aman.com | W9: Mme Sara Laghmir | X9: https://www.aman.com/resorts/amanjena | Y9: @amanresorts | Z9: https://facebook.com/amanjenaresort | AA9: Coord. complétée(s) depuis annuaire : tél | Villa(s) privatisable(s) déplacée(s) → HB-COL | AB9: ST-ULT · ULTRA EXCLUSIF | AC9: AMB-ROM · ROMANTIQUE | AD9: KD-CLB · KIDS CLUB | AE9: LVL-3 · 🔔🔔🔔 TROIS CLOCHES | AF9: À qualifier (labels / distinctions) | AG9: OR-ROM · ROMANTIQUE | AH9: PUB-CPL · Couple | AI9: ACC-PUB · ACC-PRV | AJ9: Mariage, séminaire, privatisation
